<robot name="box" xmlns:xacro="http://ros.org/wiki/xacro">


 <xacro:macro name="default_inertial" params="mass">
    <inertial>
      <mass value="${mass}"/>
      <inertia ixx="1.0" ixy="0.0" ixz="0.0" iyy="1.0" iyz="0.0" izz="1.0" />
    </inertial>
 </xacro:macro>

<link name="world"/>


<link name="box">
	<visual>
	<geometry>
		<box size="1 1 1"/>
	</geometry>
	<origin xyz= "0 0 0"/>
	</visual>
	<collision>
		<geometry>
		<box size="1 1 1"/>
		</geometry>
	<origin xyz= "0 0 0"/>
	</collision>
	<inertial>

		<mass value="1.0"/>
		<inertia ixx="0.17" ixy="0.0" ixz="0.0" iyy="0.17" iyz="0.0" izz="0.17" />
		<origin xyz= "0 0 0"/>
        </inertial>
</link> -->


<joint name="basetoworld" type="planar">
	<parent link="world"/>
	<child link="box"/>
	<origin xyz= "5 0 0.5"/>
</joint>

<gazebo reference="box">
	<mu1>1</mu1>
	<mu2>1</mu2>
	<minDepth>0</minDepth>
	<kd>1</kd>
	<kp>10000</kp>
	<maxVel>0.01</maxVel>
</gazebo> 


</robot>


